2023-12-08 17:32:14,826 ERROR scheduler Exception in Enqueue Events for Site ybenamara.example.com
Traceback (most recent call last):
  File "env/lib/python3.10/site-packages/redis/connection.py", line 1198, in get_connection
    if connection.can_read():
  File "env/lib/python3.10/site-packages/redis/connection.py", line 734, in can_read
    return self._parser.can_read(timeout)
  File "env/lib/python3.10/site-packages/redis/connection.py", line 416, in can_read
    return self.read_from_socket(timeout=timeout,
  File "env/lib/python3.10/site-packages/redis/connection.py", line 429, in read_from_socket
    raise ConnectionError(SERVER_CLOSED_CONNECTION_ERROR)
redis.exceptions.ConnectionError: Connection closed by server.

During handling of the above exception, another exception occurred:

Traceback (most recent call last):
  File "env/lib/python3.10/site-packages/redis/connection.py", line 559, in connect
    sock = self._connect()
  File "env/lib/python3.10/site-packages/redis/connection.py", line 615, in _connect
    raise err
  File "env/lib/python3.10/site-packages/redis/connection.py", line 603, in _connect
    sock.connect(socket_address)
ConnectionRefusedError: [Errno 111] Connection refused

During handling of the above exception, another exception occurred:

Traceback (most recent call last):
  File "apps/frappe/frappe/utils/scheduler.py", line 78, in enqueue_events_for_site
    enqueue_events(site=site)
  File "apps/frappe/frappe/utils/scheduler.py", line 96, in enqueue_events
    queued_jobs = get_jobs(site=site, key="job_type").get(site) or []
  File "apps/frappe/frappe/utils/background_jobs.py", line 305, in get_jobs
    jobs = q.jobs + get_running_jobs_in_queue(q)
  File "env/lib/python3.10/site-packages/rq/queue.py", line 218, in jobs
    return self.get_jobs()
  File "env/lib/python3.10/site-packages/rq/queue.py", line 207, in get_jobs
    job_ids = self.get_job_ids(offset, length)
  File "env/lib/python3.10/site-packages/rq/queue.py", line 203, in get_job_ids
    self.connection.lrange(self.key, start, end)]
  File "env/lib/python3.10/site-packages/redis/client.py", line 1975, in lrange
    return self.execute_command('LRANGE', name, start, end)
  File "env/lib/python3.10/site-packages/redis/client.py", line 898, in execute_command
    conn = self.connection or pool.get_connection(command_name, **options)
  File "env/lib/python3.10/site-packages/redis/connection.py", line 1202, in get_connection
    connection.connect()
  File "env/lib/python3.10/site-packages/redis/connection.py", line 563, in connect
    raise ConnectionError(self._error_message(e))
redis.exceptions.ConnectionError: Error 111 connecting to 127.0.0.1:11000. Connection refused.

2023-12-08 17:33:15,041 ERROR scheduler Exception in Enqueue Events for Site ybenamara.example.com
Traceback (most recent call last):
  File "env/lib/python3.10/site-packages/redis/connection.py", line 559, in connect
    sock = self._connect()
  File "env/lib/python3.10/site-packages/redis/connection.py", line 615, in _connect
    raise err
  File "env/lib/python3.10/site-packages/redis/connection.py", line 603, in _connect
    sock.connect(socket_address)
ConnectionRefusedError: [Errno 111] Connection refused

During handling of the above exception, another exception occurred:

Traceback (most recent call last):
  File "apps/frappe/frappe/utils/scheduler.py", line 78, in enqueue_events_for_site
    enqueue_events(site=site)
  File "apps/frappe/frappe/utils/scheduler.py", line 96, in enqueue_events
    queued_jobs = get_jobs(site=site, key="job_type").get(site) or []
  File "apps/frappe/frappe/utils/background_jobs.py", line 305, in get_jobs
    jobs = q.jobs + get_running_jobs_in_queue(q)
  File "env/lib/python3.10/site-packages/rq/queue.py", line 218, in jobs
    return self.get_jobs()
  File "env/lib/python3.10/site-packages/rq/queue.py", line 207, in get_jobs
    job_ids = self.get_job_ids(offset, length)
  File "env/lib/python3.10/site-packages/rq/queue.py", line 203, in get_job_ids
    self.connection.lrange(self.key, start, end)]
  File "env/lib/python3.10/site-packages/redis/client.py", line 1975, in lrange
    return self.execute_command('LRANGE', name, start, end)
  File "env/lib/python3.10/site-packages/redis/client.py", line 898, in execute_command
    conn = self.connection or pool.get_connection(command_name, **options)
  File "env/lib/python3.10/site-packages/redis/connection.py", line 1192, in get_connection
    connection.connect()
  File "env/lib/python3.10/site-packages/redis/connection.py", line 563, in connect
    raise ConnectionError(self._error_message(e))
redis.exceptions.ConnectionError: Error 111 connecting to 127.0.0.1:11000. Connection refused.

2023-12-08 17:34:15,183 ERROR scheduler Exception in Enqueue Events for Site ybenamara.example.com
Traceback (most recent call last):
  File "env/lib/python3.10/site-packages/redis/connection.py", line 559, in connect
    sock = self._connect()
  File "env/lib/python3.10/site-packages/redis/connection.py", line 615, in _connect
    raise err
  File "env/lib/python3.10/site-packages/redis/connection.py", line 603, in _connect
    sock.connect(socket_address)
ConnectionRefusedError: [Errno 111] Connection refused

During handling of the above exception, another exception occurred:

Traceback (most recent call last):
  File "apps/frappe/frappe/utils/scheduler.py", line 78, in enqueue_events_for_site
    enqueue_events(site=site)
  File "apps/frappe/frappe/utils/scheduler.py", line 96, in enqueue_events
    queued_jobs = get_jobs(site=site, key="job_type").get(site) or []
  File "apps/frappe/frappe/utils/background_jobs.py", line 305, in get_jobs
    jobs = q.jobs + get_running_jobs_in_queue(q)
  File "env/lib/python3.10/site-packages/rq/queue.py", line 218, in jobs
    return self.get_jobs()
  File "env/lib/python3.10/site-packages/rq/queue.py", line 207, in get_jobs
    job_ids = self.get_job_ids(offset, length)
  File "env/lib/python3.10/site-packages/rq/queue.py", line 203, in get_job_ids
    self.connection.lrange(self.key, start, end)]
  File "env/lib/python3.10/site-packages/redis/client.py", line 1975, in lrange
    return self.execute_command('LRANGE', name, start, end)
  File "env/lib/python3.10/site-packages/redis/client.py", line 898, in execute_command
    conn = self.connection or pool.get_connection(command_name, **options)
  File "env/lib/python3.10/site-packages/redis/connection.py", line 1192, in get_connection
    connection.connect()
  File "env/lib/python3.10/site-packages/redis/connection.py", line 563, in connect
    raise ConnectionError(self._error_message(e))
redis.exceptions.ConnectionError: Error 111 connecting to 127.0.0.1:11000. Connection refused.

2023-12-08 17:35:15,348 ERROR scheduler Exception in Enqueue Events for Site ybenamara.example.com
Traceback (most recent call last):
  File "env/lib/python3.10/site-packages/redis/connection.py", line 559, in connect
    sock = self._connect()
  File "env/lib/python3.10/site-packages/redis/connection.py", line 615, in _connect
    raise err
  File "env/lib/python3.10/site-packages/redis/connection.py", line 603, in _connect
    sock.connect(socket_address)
ConnectionRefusedError: [Errno 111] Connection refused

During handling of the above exception, another exception occurred:

Traceback (most recent call last):
  File "apps/frappe/frappe/utils/scheduler.py", line 78, in enqueue_events_for_site
    enqueue_events(site=site)
  File "apps/frappe/frappe/utils/scheduler.py", line 96, in enqueue_events
    queued_jobs = get_jobs(site=site, key="job_type").get(site) or []
  File "apps/frappe/frappe/utils/background_jobs.py", line 305, in get_jobs
    jobs = q.jobs + get_running_jobs_in_queue(q)
  File "env/lib/python3.10/site-packages/rq/queue.py", line 218, in jobs
    return self.get_jobs()
  File "env/lib/python3.10/site-packages/rq/queue.py", line 207, in get_jobs
    job_ids = self.get_job_ids(offset, length)
  File "env/lib/python3.10/site-packages/rq/queue.py", line 203, in get_job_ids
    self.connection.lrange(self.key, start, end)]
  File "env/lib/python3.10/site-packages/redis/client.py", line 1975, in lrange
    return self.execute_command('LRANGE', name, start, end)
  File "env/lib/python3.10/site-packages/redis/client.py", line 898, in execute_command
    conn = self.connection or pool.get_connection(command_name, **options)
  File "env/lib/python3.10/site-packages/redis/connection.py", line 1192, in get_connection
    connection.connect()
  File "env/lib/python3.10/site-packages/redis/connection.py", line 563, in connect
    raise ConnectionError(self._error_message(e))
redis.exceptions.ConnectionError: Error 111 connecting to 127.0.0.1:11000. Connection refused.

2023-12-08 17:36:15,547 ERROR scheduler Exception in Enqueue Events for Site ybenamara.example.com
Traceback (most recent call last):
  File "env/lib/python3.10/site-packages/redis/connection.py", line 559, in connect
    sock = self._connect()
  File "env/lib/python3.10/site-packages/redis/connection.py", line 615, in _connect
    raise err
  File "env/lib/python3.10/site-packages/redis/connection.py", line 603, in _connect
    sock.connect(socket_address)
ConnectionRefusedError: [Errno 111] Connection refused

During handling of the above exception, another exception occurred:

Traceback (most recent call last):
  File "apps/frappe/frappe/utils/scheduler.py", line 78, in enqueue_events_for_site
    enqueue_events(site=site)
  File "apps/frappe/frappe/utils/scheduler.py", line 96, in enqueue_events
    queued_jobs = get_jobs(site=site, key="job_type").get(site) or []
  File "apps/frappe/frappe/utils/background_jobs.py", line 305, in get_jobs
    jobs = q.jobs + get_running_jobs_in_queue(q)
  File "env/lib/python3.10/site-packages/rq/queue.py", line 218, in jobs
    return self.get_jobs()
  File "env/lib/python3.10/site-packages/rq/queue.py", line 207, in get_jobs
    job_ids = self.get_job_ids(offset, length)
  File "env/lib/python3.10/site-packages/rq/queue.py", line 203, in get_job_ids
    self.connection.lrange(self.key, start, end)]
  File "env/lib/python3.10/site-packages/redis/client.py", line 1975, in lrange
    return self.execute_command('LRANGE', name, start, end)
  File "env/lib/python3.10/site-packages/redis/client.py", line 898, in execute_command
    conn = self.connection or pool.get_connection(command_name, **options)
  File "env/lib/python3.10/site-packages/redis/connection.py", line 1192, in get_connection
    connection.connect()
  File "env/lib/python3.10/site-packages/redis/connection.py", line 563, in connect
    raise ConnectionError(self._error_message(e))
redis.exceptions.ConnectionError: Error 111 connecting to 127.0.0.1:11000. Connection refused.

2023-12-08 17:37:15,794 ERROR scheduler Exception in Enqueue Events for Site ybenamara.example.com
Traceback (most recent call last):
  File "env/lib/python3.10/site-packages/redis/connection.py", line 559, in connect
    sock = self._connect()
  File "env/lib/python3.10/site-packages/redis/connection.py", line 615, in _connect
    raise err
  File "env/lib/python3.10/site-packages/redis/connection.py", line 603, in _connect
    sock.connect(socket_address)
ConnectionRefusedError: [Errno 111] Connection refused

During handling of the above exception, another exception occurred:

Traceback (most recent call last):
  File "apps/frappe/frappe/utils/scheduler.py", line 78, in enqueue_events_for_site
    enqueue_events(site=site)
  File "apps/frappe/frappe/utils/scheduler.py", line 96, in enqueue_events
    queued_jobs = get_jobs(site=site, key="job_type").get(site) or []
  File "apps/frappe/frappe/utils/background_jobs.py", line 305, in get_jobs
    jobs = q.jobs + get_running_jobs_in_queue(q)
  File "env/lib/python3.10/site-packages/rq/queue.py", line 218, in jobs
    return self.get_jobs()
  File "env/lib/python3.10/site-packages/rq/queue.py", line 207, in get_jobs
    job_ids = self.get_job_ids(offset, length)
  File "env/lib/python3.10/site-packages/rq/queue.py", line 203, in get_job_ids
    self.connection.lrange(self.key, start, end)]
  File "env/lib/python3.10/site-packages/redis/client.py", line 1975, in lrange
    return self.execute_command('LRANGE', name, start, end)
  File "env/lib/python3.10/site-packages/redis/client.py", line 898, in execute_command
    conn = self.connection or pool.get_connection(command_name, **options)
  File "env/lib/python3.10/site-packages/redis/connection.py", line 1192, in get_connection
    connection.connect()
  File "env/lib/python3.10/site-packages/redis/connection.py", line 563, in connect
    raise ConnectionError(self._error_message(e))
redis.exceptions.ConnectionError: Error 111 connecting to 127.0.0.1:11000. Connection refused.

2023-12-08 17:38:16,033 ERROR scheduler Exception in Enqueue Events for Site ybenamara.example.com
Traceback (most recent call last):
  File "env/lib/python3.10/site-packages/redis/connection.py", line 559, in connect
    sock = self._connect()
  File "env/lib/python3.10/site-packages/redis/connection.py", line 615, in _connect
    raise err
  File "env/lib/python3.10/site-packages/redis/connection.py", line 603, in _connect
    sock.connect(socket_address)
ConnectionRefusedError: [Errno 111] Connection refused

During handling of the above exception, another exception occurred:

Traceback (most recent call last):
  File "apps/frappe/frappe/utils/scheduler.py", line 78, in enqueue_events_for_site
    enqueue_events(site=site)
  File "apps/frappe/frappe/utils/scheduler.py", line 96, in enqueue_events
    queued_jobs = get_jobs(site=site, key="job_type").get(site) or []
  File "apps/frappe/frappe/utils/background_jobs.py", line 305, in get_jobs
    jobs = q.jobs + get_running_jobs_in_queue(q)
  File "env/lib/python3.10/site-packages/rq/queue.py", line 218, in jobs
    return self.get_jobs()
  File "env/lib/python3.10/site-packages/rq/queue.py", line 207, in get_jobs
    job_ids = self.get_job_ids(offset, length)
  File "env/lib/python3.10/site-packages/rq/queue.py", line 203, in get_job_ids
    self.connection.lrange(self.key, start, end)]
  File "env/lib/python3.10/site-packages/redis/client.py", line 1975, in lrange
    return self.execute_command('LRANGE', name, start, end)
  File "env/lib/python3.10/site-packages/redis/client.py", line 898, in execute_command
    conn = self.connection or pool.get_connection(command_name, **options)
  File "env/lib/python3.10/site-packages/redis/connection.py", line 1192, in get_connection
    connection.connect()
  File "env/lib/python3.10/site-packages/redis/connection.py", line 563, in connect
    raise ConnectionError(self._error_message(e))
redis.exceptions.ConnectionError: Error 111 connecting to 127.0.0.1:11000. Connection refused.

2023-12-08 17:39:16,238 ERROR scheduler Exception in Enqueue Events for Site ybenamara.example.com
Traceback (most recent call last):
  File "env/lib/python3.10/site-packages/redis/connection.py", line 559, in connect
    sock = self._connect()
  File "env/lib/python3.10/site-packages/redis/connection.py", line 615, in _connect
    raise err
  File "env/lib/python3.10/site-packages/redis/connection.py", line 603, in _connect
    sock.connect(socket_address)
ConnectionRefusedError: [Errno 111] Connection refused

During handling of the above exception, another exception occurred:

Traceback (most recent call last):
  File "apps/frappe/frappe/utils/scheduler.py", line 78, in enqueue_events_for_site
    enqueue_events(site=site)
  File "apps/frappe/frappe/utils/scheduler.py", line 96, in enqueue_events
    queued_jobs = get_jobs(site=site, key="job_type").get(site) or []
  File "apps/frappe/frappe/utils/background_jobs.py", line 305, in get_jobs
    jobs = q.jobs + get_running_jobs_in_queue(q)
  File "env/lib/python3.10/site-packages/rq/queue.py", line 218, in jobs
    return self.get_jobs()
  File "env/lib/python3.10/site-packages/rq/queue.py", line 207, in get_jobs
    job_ids = self.get_job_ids(offset, length)
  File "env/lib/python3.10/site-packages/rq/queue.py", line 203, in get_job_ids
    self.connection.lrange(self.key, start, end)]
  File "env/lib/python3.10/site-packages/redis/client.py", line 1975, in lrange
    return self.execute_command('LRANGE', name, start, end)
  File "env/lib/python3.10/site-packages/redis/client.py", line 898, in execute_command
    conn = self.connection or pool.get_connection(command_name, **options)
  File "env/lib/python3.10/site-packages/redis/connection.py", line 1192, in get_connection
    connection.connect()
  File "env/lib/python3.10/site-packages/redis/connection.py", line 563, in connect
    raise ConnectionError(self._error_message(e))
redis.exceptions.ConnectionError: Error 111 connecting to 127.0.0.1:11000. Connection refused.

2023-12-08 17:40:16,375 ERROR scheduler Exception in Enqueue Events for Site ybenamara.example.com
Traceback (most recent call last):
  File "env/lib/python3.10/site-packages/redis/connection.py", line 559, in connect
    sock = self._connect()
  File "env/lib/python3.10/site-packages/redis/connection.py", line 615, in _connect
    raise err
  File "env/lib/python3.10/site-packages/redis/connection.py", line 603, in _connect
    sock.connect(socket_address)
ConnectionRefusedError: [Errno 111] Connection refused

During handling of the above exception, another exception occurred:

Traceback (most recent call last):
  File "apps/frappe/frappe/utils/scheduler.py", line 78, in enqueue_events_for_site
    enqueue_events(site=site)
  File "apps/frappe/frappe/utils/scheduler.py", line 96, in enqueue_events
    queued_jobs = get_jobs(site=site, key="job_type").get(site) or []
  File "apps/frappe/frappe/utils/background_jobs.py", line 305, in get_jobs
    jobs = q.jobs + get_running_jobs_in_queue(q)
  File "env/lib/python3.10/site-packages/rq/queue.py", line 218, in jobs
    return self.get_jobs()
  File "env/lib/python3.10/site-packages/rq/queue.py", line 207, in get_jobs
    job_ids = self.get_job_ids(offset, length)
  File "env/lib/python3.10/site-packages/rq/queue.py", line 203, in get_job_ids
    self.connection.lrange(self.key, start, end)]
  File "env/lib/python3.10/site-packages/redis/client.py", line 1975, in lrange
    return self.execute_command('LRANGE', name, start, end)
  File "env/lib/python3.10/site-packages/redis/client.py", line 898, in execute_command
    conn = self.connection or pool.get_connection(command_name, **options)
  File "env/lib/python3.10/site-packages/redis/connection.py", line 1192, in get_connection
    connection.connect()
  File "env/lib/python3.10/site-packages/redis/connection.py", line 563, in connect
    raise ConnectionError(self._error_message(e))
redis.exceptions.ConnectionError: Error 111 connecting to 127.0.0.1:11000. Connection refused.

2023-12-08 17:41:16,573 ERROR scheduler Exception in Enqueue Events for Site ybenamara.example.com
Traceback (most recent call last):
  File "env/lib/python3.10/site-packages/redis/connection.py", line 559, in connect
    sock = self._connect()
  File "env/lib/python3.10/site-packages/redis/connection.py", line 615, in _connect
    raise err
  File "env/lib/python3.10/site-packages/redis/connection.py", line 603, in _connect
    sock.connect(socket_address)
ConnectionRefusedError: [Errno 111] Connection refused

During handling of the above exception, another exception occurred:

Traceback (most recent call last):
  File "apps/frappe/frappe/utils/scheduler.py", line 78, in enqueue_events_for_site
    enqueue_events(site=site)
  File "apps/frappe/frappe/utils/scheduler.py", line 96, in enqueue_events
    queued_jobs = get_jobs(site=site, key="job_type").get(site) or []
  File "apps/frappe/frappe/utils/background_jobs.py", line 305, in get_jobs
    jobs = q.jobs + get_running_jobs_in_queue(q)
  File "env/lib/python3.10/site-packages/rq/queue.py", line 218, in jobs
    return self.get_jobs()
  File "env/lib/python3.10/site-packages/rq/queue.py", line 207, in get_jobs
    job_ids = self.get_job_ids(offset, length)
  File "env/lib/python3.10/site-packages/rq/queue.py", line 203, in get_job_ids
    self.connection.lrange(self.key, start, end)]
  File "env/lib/python3.10/site-packages/redis/client.py", line 1975, in lrange
    return self.execute_command('LRANGE', name, start, end)
  File "env/lib/python3.10/site-packages/redis/client.py", line 898, in execute_command
    conn = self.connection or pool.get_connection(command_name, **options)
  File "env/lib/python3.10/site-packages/redis/connection.py", line 1192, in get_connection
    connection.connect()
  File "env/lib/python3.10/site-packages/redis/connection.py", line 563, in connect
    raise ConnectionError(self._error_message(e))
redis.exceptions.ConnectionError: Error 111 connecting to 127.0.0.1:11000. Connection refused.

2023-12-08 17:42:16,794 ERROR scheduler Exception in Enqueue Events for Site ybenamara.example.com
Traceback (most recent call last):
  File "env/lib/python3.10/site-packages/redis/connection.py", line 559, in connect
    sock = self._connect()
  File "env/lib/python3.10/site-packages/redis/connection.py", line 615, in _connect
    raise err
  File "env/lib/python3.10/site-packages/redis/connection.py", line 603, in _connect
    sock.connect(socket_address)
ConnectionRefusedError: [Errno 111] Connection refused

During handling of the above exception, another exception occurred:

Traceback (most recent call last):
  File "apps/frappe/frappe/utils/scheduler.py", line 78, in enqueue_events_for_site
    enqueue_events(site=site)
  File "apps/frappe/frappe/utils/scheduler.py", line 96, in enqueue_events
    queued_jobs = get_jobs(site=site, key="job_type").get(site) or []
  File "apps/frappe/frappe/utils/background_jobs.py", line 305, in get_jobs
    jobs = q.jobs + get_running_jobs_in_queue(q)
  File "env/lib/python3.10/site-packages/rq/queue.py", line 218, in jobs
    return self.get_jobs()
  File "env/lib/python3.10/site-packages/rq/queue.py", line 207, in get_jobs
    job_ids = self.get_job_ids(offset, length)
  File "env/lib/python3.10/site-packages/rq/queue.py", line 203, in get_job_ids
    self.connection.lrange(self.key, start, end)]
  File "env/lib/python3.10/site-packages/redis/client.py", line 1975, in lrange
    return self.execute_command('LRANGE', name, start, end)
  File "env/lib/python3.10/site-packages/redis/client.py", line 898, in execute_command
    conn = self.connection or pool.get_connection(command_name, **options)
  File "env/lib/python3.10/site-packages/redis/connection.py", line 1192, in get_connection
    connection.connect()
  File "env/lib/python3.10/site-packages/redis/connection.py", line 563, in connect
    raise ConnectionError(self._error_message(e))
redis.exceptions.ConnectionError: Error 111 connecting to 127.0.0.1:11000. Connection refused.

2023-12-08 19:45:39,220 ERROR scheduler Exception in Enqueue Events for Site ybenamara.example.com
Traceback (most recent call last):
  File "env/lib/python3.10/site-packages/redis/connection.py", line 559, in connect
    sock = self._connect()
  File "env/lib/python3.10/site-packages/redis/connection.py", line 615, in _connect
    raise err
  File "env/lib/python3.10/site-packages/redis/connection.py", line 603, in _connect
    sock.connect(socket_address)
ConnectionRefusedError: [Errno 111] Connection refused

During handling of the above exception, another exception occurred:

Traceback (most recent call last):
  File "apps/frappe/frappe/utils/scheduler.py", line 78, in enqueue_events_for_site
    enqueue_events(site=site)
  File "apps/frappe/frappe/utils/scheduler.py", line 96, in enqueue_events
    queued_jobs = get_jobs(site=site, key="job_type").get(site) or []
  File "apps/frappe/frappe/utils/background_jobs.py", line 305, in get_jobs
    jobs = q.jobs + get_running_jobs_in_queue(q)
  File "env/lib/python3.10/site-packages/rq/queue.py", line 218, in jobs
    return self.get_jobs()
  File "env/lib/python3.10/site-packages/rq/queue.py", line 207, in get_jobs
    job_ids = self.get_job_ids(offset, length)
  File "env/lib/python3.10/site-packages/rq/queue.py", line 203, in get_job_ids
    self.connection.lrange(self.key, start, end)]
  File "env/lib/python3.10/site-packages/redis/client.py", line 1975, in lrange
    return self.execute_command('LRANGE', name, start, end)
  File "env/lib/python3.10/site-packages/redis/client.py", line 898, in execute_command
    conn = self.connection or pool.get_connection(command_name, **options)
  File "env/lib/python3.10/site-packages/redis/connection.py", line 1192, in get_connection
    connection.connect()
  File "env/lib/python3.10/site-packages/redis/connection.py", line 563, in connect
    raise ConnectionError(self._error_message(e))
redis.exceptions.ConnectionError: Error 111 connecting to 127.0.0.1:11000. Connection refused.

2023-12-08 19:46:39,367 ERROR scheduler Exception in Enqueue Events for Site ybenamara.example.com
Traceback (most recent call last):
  File "env/lib/python3.10/site-packages/redis/connection.py", line 559, in connect
    sock = self._connect()
  File "env/lib/python3.10/site-packages/redis/connection.py", line 615, in _connect
    raise err
  File "env/lib/python3.10/site-packages/redis/connection.py", line 603, in _connect
    sock.connect(socket_address)
ConnectionRefusedError: [Errno 111] Connection refused

During handling of the above exception, another exception occurred:

Traceback (most recent call last):
  File "apps/frappe/frappe/utils/scheduler.py", line 78, in enqueue_events_for_site
    enqueue_events(site=site)
  File "apps/frappe/frappe/utils/scheduler.py", line 96, in enqueue_events
    queued_jobs = get_jobs(site=site, key="job_type").get(site) or []
  File "apps/frappe/frappe/utils/background_jobs.py", line 305, in get_jobs
    jobs = q.jobs + get_running_jobs_in_queue(q)
  File "env/lib/python3.10/site-packages/rq/queue.py", line 218, in jobs
    return self.get_jobs()
  File "env/lib/python3.10/site-packages/rq/queue.py", line 207, in get_jobs
    job_ids = self.get_job_ids(offset, length)
  File "env/lib/python3.10/site-packages/rq/queue.py", line 203, in get_job_ids
    self.connection.lrange(self.key, start, end)]
  File "env/lib/python3.10/site-packages/redis/client.py", line 1975, in lrange
    return self.execute_command('LRANGE', name, start, end)
  File "env/lib/python3.10/site-packages/redis/client.py", line 898, in execute_command
    conn = self.connection or pool.get_connection(command_name, **options)
  File "env/lib/python3.10/site-packages/redis/connection.py", line 1192, in get_connection
    connection.connect()
  File "env/lib/python3.10/site-packages/redis/connection.py", line 563, in connect
    raise ConnectionError(self._error_message(e))
redis.exceptions.ConnectionError: Error 111 connecting to 127.0.0.1:11000. Connection refused.

2023-12-08 19:47:39,659 ERROR scheduler Exception in Enqueue Events for Site ybenamara.example.com
Traceback (most recent call last):
  File "env/lib/python3.10/site-packages/redis/connection.py", line 559, in connect
    sock = self._connect()
  File "env/lib/python3.10/site-packages/redis/connection.py", line 615, in _connect
    raise err
  File "env/lib/python3.10/site-packages/redis/connection.py", line 603, in _connect
    sock.connect(socket_address)
ConnectionRefusedError: [Errno 111] Connection refused

During handling of the above exception, another exception occurred:

Traceback (most recent call last):
  File "apps/frappe/frappe/utils/scheduler.py", line 78, in enqueue_events_for_site
    enqueue_events(site=site)
  File "apps/frappe/frappe/utils/scheduler.py", line 96, in enqueue_events
    queued_jobs = get_jobs(site=site, key="job_type").get(site) or []
  File "apps/frappe/frappe/utils/background_jobs.py", line 305, in get_jobs
    jobs = q.jobs + get_running_jobs_in_queue(q)
  File "env/lib/python3.10/site-packages/rq/queue.py", line 218, in jobs
    return self.get_jobs()
  File "env/lib/python3.10/site-packages/rq/queue.py", line 207, in get_jobs
    job_ids = self.get_job_ids(offset, length)
  File "env/lib/python3.10/site-packages/rq/queue.py", line 203, in get_job_ids
    self.connection.lrange(self.key, start, end)]
  File "env/lib/python3.10/site-packages/redis/client.py", line 1975, in lrange
    return self.execute_command('LRANGE', name, start, end)
  File "env/lib/python3.10/site-packages/redis/client.py", line 898, in execute_command
    conn = self.connection or pool.get_connection(command_name, **options)
  File "env/lib/python3.10/site-packages/redis/connection.py", line 1192, in get_connection
    connection.connect()
  File "env/lib/python3.10/site-packages/redis/connection.py", line 563, in connect
    raise ConnectionError(self._error_message(e))
redis.exceptions.ConnectionError: Error 111 connecting to 127.0.0.1:11000. Connection refused.

2023-12-08 19:48:39,899 ERROR scheduler Exception in Enqueue Events for Site ybenamara.example.com
Traceback (most recent call last):
  File "env/lib/python3.10/site-packages/redis/connection.py", line 559, in connect
    sock = self._connect()
  File "env/lib/python3.10/site-packages/redis/connection.py", line 615, in _connect
    raise err
  File "env/lib/python3.10/site-packages/redis/connection.py", line 603, in _connect
    sock.connect(socket_address)
ConnectionRefusedError: [Errno 111] Connection refused

During handling of the above exception, another exception occurred:

Traceback (most recent call last):
  File "apps/frappe/frappe/utils/scheduler.py", line 78, in enqueue_events_for_site
    enqueue_events(site=site)
  File "apps/frappe/frappe/utils/scheduler.py", line 96, in enqueue_events
    queued_jobs = get_jobs(site=site, key="job_type").get(site) or []
  File "apps/frappe/frappe/utils/background_jobs.py", line 305, in get_jobs
    jobs = q.jobs + get_running_jobs_in_queue(q)
  File "env/lib/python3.10/site-packages/rq/queue.py", line 218, in jobs
    return self.get_jobs()
  File "env/lib/python3.10/site-packages/rq/queue.py", line 207, in get_jobs
    job_ids = self.get_job_ids(offset, length)
  File "env/lib/python3.10/site-packages/rq/queue.py", line 203, in get_job_ids
    self.connection.lrange(self.key, start, end)]
  File "env/lib/python3.10/site-packages/redis/client.py", line 1975, in lrange
    return self.execute_command('LRANGE', name, start, end)
  File "env/lib/python3.10/site-packages/redis/client.py", line 898, in execute_command
    conn = self.connection or pool.get_connection(command_name, **options)
  File "env/lib/python3.10/site-packages/redis/connection.py", line 1192, in get_connection
    connection.connect()
  File "env/lib/python3.10/site-packages/redis/connection.py", line 563, in connect
    raise ConnectionError(self._error_message(e))
redis.exceptions.ConnectionError: Error 111 connecting to 127.0.0.1:11000. Connection refused.

2023-12-08 19:49:40,120 ERROR scheduler Exception in Enqueue Events for Site ybenamara.example.com
Traceback (most recent call last):
  File "env/lib/python3.10/site-packages/redis/connection.py", line 559, in connect
    sock = self._connect()
  File "env/lib/python3.10/site-packages/redis/connection.py", line 615, in _connect
    raise err
  File "env/lib/python3.10/site-packages/redis/connection.py", line 603, in _connect
    sock.connect(socket_address)
ConnectionRefusedError: [Errno 111] Connection refused

During handling of the above exception, another exception occurred:

Traceback (most recent call last):
  File "apps/frappe/frappe/utils/scheduler.py", line 78, in enqueue_events_for_site
    enqueue_events(site=site)
  File "apps/frappe/frappe/utils/scheduler.py", line 96, in enqueue_events
    queued_jobs = get_jobs(site=site, key="job_type").get(site) or []
  File "apps/frappe/frappe/utils/background_jobs.py", line 305, in get_jobs
    jobs = q.jobs + get_running_jobs_in_queue(q)
  File "env/lib/python3.10/site-packages/rq/queue.py", line 218, in jobs
    return self.get_jobs()
  File "env/lib/python3.10/site-packages/rq/queue.py", line 207, in get_jobs
    job_ids = self.get_job_ids(offset, length)
  File "env/lib/python3.10/site-packages/rq/queue.py", line 203, in get_job_ids
    self.connection.lrange(self.key, start, end)]
  File "env/lib/python3.10/site-packages/redis/client.py", line 1975, in lrange
    return self.execute_command('LRANGE', name, start, end)
  File "env/lib/python3.10/site-packages/redis/client.py", line 898, in execute_command
    conn = self.connection or pool.get_connection(command_name, **options)
  File "env/lib/python3.10/site-packages/redis/connection.py", line 1192, in get_connection
    connection.connect()
  File "env/lib/python3.10/site-packages/redis/connection.py", line 563, in connect
    raise ConnectionError(self._error_message(e))
redis.exceptions.ConnectionError: Error 111 connecting to 127.0.0.1:11000. Connection refused.

2023-12-08 19:50:40,300 ERROR scheduler Exception in Enqueue Events for Site ybenamara.example.com
Traceback (most recent call last):
  File "env/lib/python3.10/site-packages/redis/connection.py", line 559, in connect
    sock = self._connect()
  File "env/lib/python3.10/site-packages/redis/connection.py", line 615, in _connect
    raise err
  File "env/lib/python3.10/site-packages/redis/connection.py", line 603, in _connect
    sock.connect(socket_address)
ConnectionRefusedError: [Errno 111] Connection refused

During handling of the above exception, another exception occurred:

Traceback (most recent call last):
  File "apps/frappe/frappe/utils/scheduler.py", line 78, in enqueue_events_for_site
    enqueue_events(site=site)
  File "apps/frappe/frappe/utils/scheduler.py", line 96, in enqueue_events
    queued_jobs = get_jobs(site=site, key="job_type").get(site) or []
  File "apps/frappe/frappe/utils/background_jobs.py", line 305, in get_jobs
    jobs = q.jobs + get_running_jobs_in_queue(q)
  File "env/lib/python3.10/site-packages/rq/queue.py", line 218, in jobs
    return self.get_jobs()
  File "env/lib/python3.10/site-packages/rq/queue.py", line 207, in get_jobs
    job_ids = self.get_job_ids(offset, length)
  File "env/lib/python3.10/site-packages/rq/queue.py", line 203, in get_job_ids
    self.connection.lrange(self.key, start, end)]
  File "env/lib/python3.10/site-packages/redis/client.py", line 1975, in lrange
    return self.execute_command('LRANGE', name, start, end)
  File "env/lib/python3.10/site-packages/redis/client.py", line 898, in execute_command
    conn = self.connection or pool.get_connection(command_name, **options)
  File "env/lib/python3.10/site-packages/redis/connection.py", line 1192, in get_connection
    connection.connect()
  File "env/lib/python3.10/site-packages/redis/connection.py", line 563, in connect
    raise ConnectionError(self._error_message(e))
redis.exceptions.ConnectionError: Error 111 connecting to 127.0.0.1:11000. Connection refused.

2023-12-08 19:51:40,603 ERROR scheduler Exception in Enqueue Events for Site ybenamara.example.com
Traceback (most recent call last):
  File "env/lib/python3.10/site-packages/redis/connection.py", line 559, in connect
    sock = self._connect()
  File "env/lib/python3.10/site-packages/redis/connection.py", line 615, in _connect
    raise err
  File "env/lib/python3.10/site-packages/redis/connection.py", line 603, in _connect
    sock.connect(socket_address)
ConnectionRefusedError: [Errno 111] Connection refused

During handling of the above exception, another exception occurred:

Traceback (most recent call last):
  File "apps/frappe/frappe/utils/scheduler.py", line 78, in enqueue_events_for_site
    enqueue_events(site=site)
  File "apps/frappe/frappe/utils/scheduler.py", line 96, in enqueue_events
    queued_jobs = get_jobs(site=site, key="job_type").get(site) or []
  File "apps/frappe/frappe/utils/background_jobs.py", line 305, in get_jobs
    jobs = q.jobs + get_running_jobs_in_queue(q)
  File "env/lib/python3.10/site-packages/rq/queue.py", line 218, in jobs
    return self.get_jobs()
  File "env/lib/python3.10/site-packages/rq/queue.py", line 207, in get_jobs
    job_ids = self.get_job_ids(offset, length)
  File "env/lib/python3.10/site-packages/rq/queue.py", line 203, in get_job_ids
    self.connection.lrange(self.key, start, end)]
  File "env/lib/python3.10/site-packages/redis/client.py", line 1975, in lrange
    return self.execute_command('LRANGE', name, start, end)
  File "env/lib/python3.10/site-packages/redis/client.py", line 898, in execute_command
    conn = self.connection or pool.get_connection(command_name, **options)
  File "env/lib/python3.10/site-packages/redis/connection.py", line 1192, in get_connection
    connection.connect()
  File "env/lib/python3.10/site-packages/redis/connection.py", line 563, in connect
    raise ConnectionError(self._error_message(e))
redis.exceptions.ConnectionError: Error 111 connecting to 127.0.0.1:11000. Connection refused.

